Workbook

Sheet CODE PC
A1: Code | B1: Poste comptable | C1: Code
A2: 001 | B2: ACCTDP | C2: 001
A3: 002 | B3: RGA | C3: 002
A4: 003 | B4: PP Faravohitra | C4: 003
A5: 004 | B5: PP Isotry | C5: 004
A6: 005 | B6: PP Ankadifotsy | C6: 005
A7: 006 | B7: PP Mahazoarivo | C7: 006
A8: 007 | B8: PP Besarety | C8: 007
A9: 008 | B9: PP Mahamasina | C9: 008
A10: 009 | B10: PP Ambatomainty | C10: 009
A11: 010 | B11: PP Anosipatrana | C11: 010
A12: 011 | B12: PP Ambohimanarina | C12: 011
... A129: 128 | B129: TPIC Moramanga | C129: 128

Sheet DONNEES
A1: COMPTE | B1: 6231 Frais de déplacement intérieur
B2: 6241 Indemnités de mission intérieure
A4: ACTIVITES | B4: ASSURER LES GARDES PERMANENTES DES POSTES COMPTABLES | C4: 117-1-1-1-01
B5: ASSURER LES APPROVISIONNEMENTS EN FONDS DU RÉSEAU COMPTABLE | C5: 117-1-1-1-02
A8: NATURE DE LA DEPENSE | B8: INDEMNITE DE GARDE PERMANENTE | C8: ANNEXE 2
B9: INDEMNITE D'APPROVISIONNEMENT DE FONDS | C9: ANNEXE 3
B10: FRAIS DE DEPLACEMENT INTERIEUR | C10: ANNEXE 1
A13: PIECES JUSTIFICATIVES | B13: Ordre de Paiement
B14: Ordre de Route
B15: Ordre de Mission
B16: Etat de Décompte d'Indemnité de Garde Permanente
B17: Billet
B18: Ticket
B19: Reçu
B22: ="Paiement de frais de déplacement intérieur lors de l'approvisionnement de fonds à "&SAISIE!B11&" a/n de "&SAISIE!B19&" au titre du mois de (d') "&SAISIE!B12&" Poste Comptable : "&SAISIE!B5 -> Paiement de frais de déplacement intérieur lors de l'approvisionnement de fonds à a/n de ANDRIAMIALISON Johany Michael au titre du mois de (d') Mai à Août 2026 Poste Comptable : PP Marovoay
B24: ="Paiement d'indemnité(s) de mission intérieure de garde permanente a/n de "&SAISIE!B19&" au titre du mois de (d') "&SAISIE!B12&" auprès de la "&SAISIE!B5 -> Paiement d'indemnité(s) de mission intérieure de garde permanente a/n de ANDRIAMIALISON Johany Michael au titre du mois de (d') Mai à Août 2026 auprès de la PP Marovoay
B26: ="Paiement d'indemnité(s) de mission intérieure lors de l'approvisionnement de fonds à "&SAISIE!B11&" a/n de "&SAISIE!B19&" au titre du mois de (d') "&SAISIE!B12&" Poste Comptable : "&SAISIE!B5 -> Paiement d'indemnité(s) de mission intérieure lors de l'approvisionnement de fonds à a/n de ANDRIAMIALISON Johany Michael au titre du mois de (d') Mai à Août 2026 Poste Comptable : PP Marovoay

Sheet SAISIE
A1: (Veuillez compléter les cellules blanches) | L1: NATURE DE LA DEPENSE | M1: INDEMNITE DE GARDE PERMANENTE | N1: ANNEXE 2 | O1: Code | P1: Poste comptable | Q1: Code
A2: NATURE DE LA DEPENSE | B2: INDEMNITE DE GARDE PERMANENTE | C2: (Veuillez choisir parmi les modalités proposées dans la liste déroulante) | M2: INDEMNITE D'APPROVISIONNEMENT DE FONDS | N2: ANNEXE 3 | O2: 003 | P2: PP Faravohitra | Q2: 003
M3: FRAIS DE DEPLACEMENT INTERIEUR | N3: ANNEXE 1 | O3: 004 | P3: PP Isotry | Q3: 004
A4: CODE POSTE COMPTABLE | B4: 030 | C4: (Veuillez choisir parmi les modalités proposées dans la liste déroulante) | O4: 005 | P4: PP Ankadifotsy | Q4: 005
A5: POSTE COMPTABLE | B5: =IF(B4="","",VLOOKUP(B4,'CODE PC'!A2:B129,2,FALSE())) -> PP Marovoay | O5: 006 | P5: PP Mahazoarivo | Q5: 006
A6: NUMERO OP | B6: 029 | O6: 007 | P6: PP Besarety | Q6: 007
A7: INTITULE ACTIVITE | B7: =IF(B2="","",IF(SAISIE!B2=DONNEES!B8,DONNEES!B4,IF(SAISIE!B2=DONNEES!B9,DONNEES!B5,DONNEES!B5))) -> ASSURER LES GARDES PERMANENTES DES POSTES COMPTABLES | O7: 008 | P7: PP Mahamasina | Q7: 008
A8: CODE ACTIVITE | B8: =IF(B7="","",VLOOKUP(B7,DONNEES!B4:C5,2,FALSE())) -> 117-1-1-1-01 | O8: 009 | P8: PP Ambatomainty | Q8: 009
A9: COMPTE | B9: =IF(B2="","",IF(B2=DONNEES!B8,DONNEES!B2,IF(SAISIE!B2=DONNEES!B9,DONNEES!B2,DONNEES!B1))) -> 6241 Indemnités de mission intérieure | O9: 010 | P9: PP Anosipatrana | Q9: 10
O10: 011 | P10: PP Ambohimanarina | Q10: 11
A11: =IF(OR(B2=DONNEES!B9,B2=DONNEES!B10),"LIEU DE L'APPROVISIONNEMENT DE FONDS","NE PAS COMPLETER") -> NE PAS COMPLETER | O11: 013 | P11: PP Atsimondrano | Q11: 013
A12: =IF(OR(B2=DONNEES!B9,B2=DONNEES!B10),"MOIS DE L'APPROVISIONNEMENT DE FONDS","MOIS DE LA GARDE") -> MOIS DE LA GARDE | B12: Mai à Août 2026 | O12: 014 | P12: PP Avaradrano | Q12: 014
O13: 015 | P13: PP Ambohidratrimo | Q13: 015
O14: 016 | P14: PP Andramasina | Q14: 016
A15: MONTANT à PAYER (en Ariary) | B15: 330000 | O15: 017 | P15: PP Anjozorobe | Q15: 017
A16: EN LETTRE | B16: =chiffrelettre(B15) -> #VALUE! | O16: 018 | P16: PP Ankazobe | Q16: 018
O17: 019 | P17: PP Manjakandriana | Q17: 019
B18: TITULAIRE | O18: 020 | P18: TG Antsiranana | Q18: 020
A19: NOM ET PRENOMS | B19: ANDRIAMIALISON Johany Michael | O19: 021 | P19: PP Ambilobe | Q19: 021
A20: IM | B20: 357484 | C20: (Si Gendarme, veuillez écrire sous la forme "Gxxxxx". Exemple : G12345) | O20: 022 | P20: TG Toamasina | Q20: 022
A21: CIN | B21: 101221096930 | O21: 023 | P21: PP Antanambao Manampontsy | Q21: 023
A22: ADRESSE | B22: CSP MAROVOAY | O22: 024 | P22: PP Brickaville | Q22: 024
O23: 025 | P23: PP Mahanoro | Q23: 025
A24: LIEU D'EDITION DE L'OP | B24: Marovoay | O24: 026 | P24: PP Marolambo | Q24: 026
A25: ANNEE D'EDITION DE L'OP | B25: 2026 | O25: 027 | P25: PP Vatomandry | Q25: 027
A26: DATE D'EDITION DE L'OP | B26: 01/10/2026 | O26: 028 | P26: TG Mahajanga | Q26: 028
O27: 029 | P27: PP Ambatoboeny | Q27: 029
A28: OBJET DE LA DEPENSE | B28: =IF(B2="","",IF(B2=DONNEES!B8,DONNEES!B24,IF(B2=DONNEES!B9,DONNEES!B26,DONNEES!B22))) -> Paiement d'indemnité(s) de mission intérieure de garde permanente a/n de ANDRIAMIALISON Johany Michael au titre du mois de (d') Mai à Août 2026 auprès de la PP Marovoay | O28: 030 | P28: PP Marovoay | Q28: 030
O29: 031 | P29: PP Mitsinjo | Q29: 031
O30: 032 | P30: PP Soalala | Q30: 032
O31: 033 | P31: TG Fianarantsoa | Q31: 033
O32: 034 | P32: PP Ambalavao | Q32: 034
O33: 035 | P33: PP Ambohimahasoa | Q33: 035
O34: 036 | P34: PP Ikalamavony | Q34: 036
O35: 037 | P35: TG Toliara | Q35: 037
O36: 038 | P36: PP Ampanihy | Q36: 038
O37: 039 | P37: PP Ankazoabo | Q37: 039
O38: 040 | P38: PP Benenitra | Q38: 040
O39: 041 | P39: PP Beroroha | Q39: 041
O40: 042 | P40: PP Betioky sud | Q40: 042
...

Sheet OP à imprimer
A2: MINISTERE | B2: 21 MEF | D2: REPUBLIQUE DE MADAGASCAR | H2: N° BE
A3: ORDONNATEUR | B3: 00-22Y-8-00000 | D3: MISSION : | E3: 220 | F3: EXERCICE : | G3: =IF(SAISIE!B25<>"",SAISIE!B25,"") -> 2026
A4: COMMUNE BENEFICIAIRE | B4: 00000 | D4: BUDGET : | E4: 00 | F4: CATEGORIE : | G4: 3
D5: ORDRE DE PAIEMENT
A6: CODE CF | B6: 10101.220 | H6: N° OP : | I6: =SAISIE!B25&" / "&SAISIE!B4&" / "&SAISIE!B6 -> 2026 / 030 / 029
A7: TP ASSIGNATAIRE | B7: 10101.100 | D7: En vertu des crédits sur le paragraphe ci-dessous, l’ordonnateur soussigné mandate les créances ci-après
A9: PROGRAMME | D9: 117 | H9: SECT-CONV : 000 RESSOURCES PROPRES
A10: ACTIVITE PROJET | D10: =SAISIE!B8 -> 117-1-1-1-01
A11: IMPUTATION ADMINISTRATIVE - CDD | D11: 00-21-T-223-00000 | H11: FINANCEMENT : | J11: 10-001-001-A
A12: COMPTE | D12: =IF(SAISIE!B9<>"",SAISIE!B9,"") -> 6241 Indemnités de mission intérieure
A14: LIQUIDATION DE LA DEPENSE | F14: REGLEMENT DE LA CREANCE
A15: Pièces justificatives : | B15: =IF(SAISIE!B2="INDEMNITE DE GARDE PERMANENTE","- Ordre de mission - Etat de décompte",IF(SAISIE!B2="INDEMNITE D'APPROVISIONNEMENT DE FONDS","Ordre de route",IF(SAISIE!B2="FRAIS DE DEPLACEMENT INTERIEUR","- Photocopie certifiée de l'ordre de route - Billet",""))) -> - Ordre de mission - Etat de décompte | F15: (Modalités de REGLEMENT)
F16: BON DE CAISSE | I16: VIREMENT BANCAIRE
F17: AUTRE VIREMENT | I17: OPERATION D'ORDRE
A19: MONTANT LIQUIDE HT | C19: =SAISIE!B15 -> 330000 | F19: Descriptif de l’opération d’ordre | I19: Cadre réservé au comptable
A20: TAXES (TTL, DTI) | C20: 0 | F20: COMPTE A CREDITER
A21: MONTANT LIQUIDE | C21: =C19+C20 -> 330000 | F21: POSTE COMPTABLE
A22: DEPENSES EN DEVISES | F22: EN REGLEMENT
A23: MONTANT CONTRACTUEL | F23: Ordre de recette (OR) | I23: Préc.
A24: DEVISE | F24: Dépenses à régul. (DAR) | I24: AUTRE
A25: COURS | F25: Préciser
A26: PERIODE LIQUIDEE
A27: DATE DEBUT | C27: DATE FACTURATION
A28: DATE FIN | F28: VISA DU COMPTABLE
A29: DISPONIBILITE SUR ENGAGEMENT : DEV / AR
A30: ENGAGEMENT INITIAL
A31: CUMUL MANDATE
A32: MONTANT MANDATE | F32: Numéro d'identification du TITULAIRE : | J32: =IF(SAISIE!B20<>"","F00"&SAISIE!B20,"") -> F00357484
A33: Disponible sur ENGAGEMENT
A34: Objet de la dépense : | F34: TITULAIRE : | G34: =IF(SAISIE!B19<>"",SAISIE!B19,"") -> ANDRIAMIALISON Johany Michael
A35: =SAISIE!B28 -> Paiement d'indemnité(s) de mission intérieure de garde permanente a/n de ANDRIAMIALISON Johany Michael au titre du mois de (d') Mai à Août 2026 auprès de la PP Marovoay
F37: CIN : | G37: =IF(SAISIE!B21<>"",SAISIE!B21,"") -> 101221096930
A38: MONTANT MANDATE (A) | C38: =C21 -> 330000 | F38: ADRESSE : | G38: =IF(SAISIE!B22<>"",SAISIE!B22,"") -> CSP MAROVOAY
A39: A PRECOMPTER | C39: 0
A40: NET A PAYER | C40: =C38+C39 -> 330000
A41: ARRETE par nous le présent ordre de paiement à la somme de (A) : | F41: Pour acquit de la somme indiquée ci-contre (A) A......................................................................... Le........................................................................
A42: =SAISIE!B16 -> #VALUE!
A43: ="Fait à "&SAISIE!B24&", le "&SAISIE!B26&" (Signature et timbre du Chef de Poste)" -> Fait à Marovoay, le 01/10/2026 (Signature et timbre du Chef de Poste)
